Workbook

Sheet Cover
B2: Airbnb, Inc.
B3: DCF valuation and trading comparables
B4: Nasdaq: ABNB | USD
B6: Result
B7: DCF value per share (USD) | C7: =DCF!$C$42 -> 115.68823
B8: Share price (USD) | C8: =Inputs!$B$6 -> 162.43
B9: Analysis date | C9: =Inputs!$B$7 -> 46297
B10: Upside / (downside) | C10: =DCF!$C$44 -> -0.28776564
B11: Rating | C11: =DCF!$C$45 -> SELL
B12: WACC | C12: =WACC!B15 -> 0.10030562
B13: Terminal growth | C13: =DCF!I6 -> 0.03
B14: Value with SBC ignored (USD) | C14: =DCF!F80 -> 159.05729 | D14: same forecast, but SBC added back to FCF
B16: Comments
B17: - Great business: asset-light, bookings growing ~10% a year, a stable take rate and FCF close to 40% of revenue.
B18: - The problem is SBC: ~USD 1.6bn a year, about a third of FCF. If I count it as a real cost, the shares are worth clearly less than the price. If I ignore it, the DCF lands almost exactly on the price.
B19: - My forecast is close to consensus, so the gap to the analysts' average target (USD 184) comes from two things: SBC treated as a cost and a higher cost of capital (10y Treasury above 5%).
B20: - What would change my mind: services, experiences or hotels showing up in revenue, or SBC dropping well below 10% of revenue.
B22: Sheets
B23: Inputs | C23: Market data, balance sheet, cost of capital inputs
B24: Historicals | C24: FY2022-2025 and H1 2025/26: P&L, cash flow, operating metrics, ratios
B25: WACC | C25: Cost of equity, cost of debt, WACC
B26: DCF | C26: Assumptions, free cash flow 2026-2030, terminal value, sensitivity tables
B27: Comps | C27: Online travel agencies and hotel franchisors
B28: Football Field | C28: All valuation methods in one chart
B29: Charts | C29: Four charts behind the SELL call
B30: Sources | C30: Links to all documents used
B31: Colour code
B32: Blue text | C32: Input (from a source or my own assumption)
B33: Black text | C33: Formula
B34: Green text | C34: Link to another sheet
B35: Yellow fill | C35: Key assumption
B37: Personal learning project. Not investment advice.

Sheet Inputs
A1: Inputs
A2: Blue = hard-coded input, black = formula, green = link to another sheet. USD million unless stated.
A4: Item | B4: Value | C4: Unit | D4: Source / comment
A5: Market data
A6: Share price | B6: 162.43 | C6: USD | D6: Nasdaq close 02.10.2026 (MarketScreener)
A7: Analysis date | B7: 46297
A8: Shares outstanding (Class A + B + H) | B8: 598.786 | C8: m | D8: 10-Q Q2 2026 cover page, as of 15.07.2026. Only for market cap
A9: Diluted shares, FY2025 average | B9: 623 | C9: m | D9: Q4 2025 shareholder letter. Diluted count in the DCF, so unvested RSUs are included
A11: Balance sheet at 31.12.2025 (valuation date)
A12: Valuation date | B12: 46022 | D12: Last full-year balance sheet
A13: Cash and cash equivalents | B13: 6560 | C13: USDm | D13: Q4 2025 shareholder letter, balance sheet
A14: Short-term investments | B14: 4454 | C14: USDm | D14: Same as above
A15: Debt (0% convertible notes due March 2026) | B15: 1999 | C15: USDm | D15: Same as above. Repaid at par in March 2026 (refinanced with senior notes), so I treat it as debt
A16: Net cash | B16: =B13+B14-B15 -> 9015 | C16: USDm | D16: Excl. customer funds (see below)
A17: Memo: funds held on behalf of customers | B17: 6959 | C17: USDm | D17: Guest money held until check-in. The same amount sits on the liability side, so it's not Airbnb's cash
A19: Cost of capital
A20: Risk-free rate (10y US Treasury) | B20: 0.0528 | C20: % | D20: ycharts, 10-year Treasury rate, 02.10.2026
A21: Equity risk premium | B21: 0.0423 | C21: % | D21: Damodaran implied ERP for the S&P 500, start of August 2026
A22: Raw beta (5y monthly) | B22: 1.24 | D22: Yahoo Finance, October 2026
A23: Pre-tax cost of debt | B23: 0.0476 | C23: % | D23: Weighted coupon of the USD 2.5bn senior notes issued March 2026 (4.40% / 4.65% / 5.25%)
A24: Debt for capital weights | B24: 2476 | C24: USDm | D24: Form 10-Q Q2 2026: long-term debt, net, 30.06.2026
A25: Tax rate | B25: 0.21 | C25: % | D25: Effective rate 2025: 20.0% (626 / 3,137). Rounded to the US federal rate
A27: Other
A28: Rating threshold (BUY above +15%, SELL below -15%) | B28: 0.15 | C28: % | D28: My own rule: HOLD if value is within 15% of the price
A29: Years from valuation date to analysis date | B29: =(B7-B12)/365 -> 0.75342466 | C29: years
A30: Analyst price targets: low | B30: 135 | C30: USD | D30: MarketScreener consensus (43 analysts, average USD 183.56), October 2026
A31: Analyst price targets: high | B31: 220 | C31: USD | D31: Same as above
A32: 52-week low | B32: 110.81 | C32: USD | D32: Yahoo Finance and bullfincher.io, October 2026
A33: 52-week high | B33: 193.45 | C33: USD | D33: Same as above

Sheet Historicals
A1: Historical figures
A2: USD million unless stated. Fiscal year = calendar year. H1 = January to June. n.m. = not meaningful.
A4: USD m | B4: FY2022 | C4: FY2023 | D4: FY2024 | E4: FY2025 | F4: H1 2025 | G4: H1 2026 | H4: Source
A5: Income statement
A6: Revenue | B6: 8399 | C6: 9917 | D6: 11102 | E6: 12241 | F6: 5368 | G6: 6286 | H6: Q4 2023 shareholder letter (2022-23); Q4 2025 shareholder letter (2024-25); Q2 2026 shareholder letter (H1)
A7: Cost of revenue | B7: 1499 | C7: 1703 | D7: 1878 | E7: 2086 | F7: 1050 | G7: 1214 | H7: Q4 2023 shareholder letter (2022-23); Q4 2025 shareholder letter (2024-25); Q2 2026 shareholder letter (H1)
A8: Operations and support | B8: 1041 | C8: 1186 | D8: 1282 | E8: 1327 | F8: 635 | G8: 687
A9: Product development | B9: 1502 | C9: 1722 | D9: 2056 | E9: 2354 | F9: 1178 | G9: 1310
A10: Sales and marketing | B10: 1516 | C10: 1763 | D10: 2148 | E10: 2588 | F10: 1254 | G10: 1626
A11: General and administrative | B11: 950 | C11: 2025 | D11: 1185 | E11: 1342 | F11: 601 | G11: 605 | H11: 2023 includes about USD 935m of one-off lodging-tax and withholding reserves
A12: Restructuring | B12: 89 | C12: 0 | D12: 0 | E12: 0 | F12: 0 | G12: 0
A13: Income from operations (EBIT) | B13: =B6-SUM(B7:B12) -> 1802 | C13: =C6-SUM(C7:C12) -> 1518 | D13: =D6-SUM(D7:D12) -> 2553 | E13: =E6-SUM(E7:E12) -> 2544 | F13: =F6-SUM(F7:F12) -> 650 | G13: =G6-SUM(G7:G12) -> 844 | H13: Calc.; ties to reported EBIT 1,802 / 1,518 / 2,553 / 2,544 / 650 / 844
A14: Interest income | B14: 186 | C14: 721 | D14: 818 | E14: 705 | F14: 363 | G14: 338 | H14: Q4 2023 shareholder letter (2022-23); Q4 2025 shareholder letter (2024-25); Q2 2026 shareholder letter (H1)
A15: Interest expense and other income (expense), net | B15: 1 | C15: -137 | D15: -40 | E15: -112 | F15: -61 | G15: -4 | H15: One line in 2024-25. For 2022-23 and H1 I added interest expense and other income together
A16: Income before taxes | B16: =B13+B14+B15 -> 1989 | C16: =C13+C14+C15 -> 2102 | D16: =D13+D14+D15 -> 3331 | E16: =E13+E14+E15 -> 3137 | F16: =F13+F14+F15 -> 952 | G16: =G13+G14+G15 -> 1178 | H16: Calc.; ties to reported pre-tax income 1,989 / 2,102 / 3,331 / 3,137 / 952 / 1,178
A17: Income taxes (benefit) | B17: 96 | C17: -2690 | D17: 683 | E17: 626 | F17: 156 | G17: 202 | H17: 2023: benefit from releasing the valuation allowance on deferred tax assets
A18: Net income | B18: =B16-B17 -> 1893 | C18: =C16-C17 -> 4792 | D18: =D16-D17 -> 2648 | E18: =E16-E17 -> 2511 | F18: =F16-F17 -> 796 | G18: =G16-G17 -> 976 | H18: Calc.; ties to reported net income 1,893 / 4,792 / 2,648 / 2,511 / 796 / 976
A20: Cash flow and shares
A21: Operating cash flow | B21: 3430 | C21: 3884 | D21: 4518 | E21: 4646 | F21: 2764 | G21: 2978 | H21: Q4 2023 shareholder letter (2022-23); Q4 2025 shareholder letter (2024-25); Q2 2026 shareholder letter (H1)
A22: Free cash flow | B22: 3405 | C22: 3837 | D22: 4484 | E22: 4613 | F22: 2743 | G22: 2957 | H22: FY reported; H1 = Q1 + Q2
A23: Capex (operating cash flow - free cash flow) | B23: =B21-B22 -> 25 | C23: =C21-C22 -> 47 | D23: =D21-D22 -> 34 | E23: =E21-E22 -> 33 | F23: =F21-F22 -> 21 | G23: =G21-G22 -> 21 | H23: Calculated
A24: Stock-based compensation | B24: 930 | C24: 1120 | D24: 1407 | E24: 1592 | F24: 782 | G24: 897 | H24: FY reported; H1 = Q1 + Q2 from the adj. EBITDA reconciliation
A25: Share repurchases | B25: 1500 | C25: 2252 | D25: 3430 | E25: 3789 | F25: 1817 | G25: 2139 | H25: Q4 2023 shareholder letter (2022-23); Q4 2025 shareholder letter (2024-25); Q2 2026 shareholder letter (H1)
A26: Diluted shares, weighted average (m) | B26: 680 | C26: 662 | D26: 645 | E26: 623 | F26: 629 | G26: 602 | H26: Q4 2023 shareholder letter (2022-23); Q4 2025 shareholder letter (2024-25); Form 10-Q Q2 2026 (H1)
A28: Operating metrics
A29: Nights and seats booked (m) | B29: 393.7 | C29: 448.2 | D29: 491.5 | E29: 533 | F29: 277.5 | G29: 304.5 | H29: Q4 2023 shareholder letter (2022-23); Q4 2025 shareholder letter (2024-25); Q2 2026 shareholder letter (H1)
A30: Gross booking value (USD bn) | B30: 63.2 | C30: 73.3 | D30: 81.8 | E30: 91.3 | F30: 48 | G30: 56.4 | H30: Q4 2023 shareholder letter (2022-23); Q4 2025 shareholder letter (2024-25); Q2 2026 shareholder letter (H1)
A31: Average daily rate (USD, GBV / nights) | B31: =B30*1000/B29 -> 160.52832 | C31: =C30*1000/C29 -> 163.54306 | D31: =D30*1000/D29 -> 166.4293 | E31: =E30*1000/E29 -> 171.29456 | F31: =F30*1000/F29 -> 172.97297 | G31: =G30*1000/G29 -> 185.22167 | H31: Calculated
A33: Ratios
A34: Revenue growth | B34: =B6/B61-1 -> 0.40170227 | C34: =C6/B6-1 -> 0.1807358 | D34: =D6/C6-1 -> 0.11949178 | E34: =E6/D6-1 -> 0.10259413 | F34: =F6/F61-1 -> 0.097750511 | G34: =G6/F6-1 -> 0.17101341 | H34: FY2022 and H1 2025 growth: base periods at the bottom of the sheet
A35: Nights growth | B35: =B29/B62-1 -> 0.30971391 | C35: =C29/B29-1 -> 0.13843028 | D35: =D29/C29-1 -> 0.096608657 | E35: =E29/D29-1 -> 0.084435402 | F35: =F29/F62-1 -> 0.076833527 | G35: =G29/F29-1 -> 0.097297297
A36: ADR growth | B36: =B31/B64-1 -> 0.028887277 | C36: =C31/B31-1 -> 0.018780113 | D36: =D31/C31-1 -> 0.017648177 | E36: =E31/D31-1 -> 0.0292332 | F36: =F31/F64-1 -> 0.010774039 | G36: =G31/F31-1 -> 0.070812808
A37: Take rate (revenue / GBV) | B37: =B6/(B30*1000) -> 0.13289557 | C37: =C6/(C30*1000) -> 0.13529332 | D37: =D6/(D30*1000) -> 0.13572127 | E37: =E6/(E30*1000) -> 0.13407448 | F37: n.m. | G37: n.m. | H37: n.m. for H1: GBV counts at booking, revenue only at check-in
A38: Gross margin | B38: =1-B7/B6 -> 0.82152637 | C38: =1-C7/C6 -> 0.82827468 | D38: =1-D7/D6 -> 0.83084129 | E38: =1-E7/E6 -> 0.82958909 | F38: =1-F7/F6 -> 0.80439642 | G38: =1-G7/G6 -> 0.80687241
A39: Sales and marketing in % of revenue | B39: =B10/B6 -> 0.18049768 | C39: =C10/C6 -> 0.17777554 | D39: =D10/D6 -> 0.19347865 | E39: =E10/E6 -> 0.21142064 | F39: =F10/F6 -> 0.23360656 | G39: =G10/G6 -> 0.25867006
A40: Product development in % of revenue | B40: =B9/B6 -> 0.17883081 | C40: =C9/C6 -> 0.17364122 | D40: =D9/D6 -> 0.18519186 | E40: =E9/E6 -> 0.19230455 | F40: =F9/F6 -> 0.21944858 | G40: =G9/G6 -> 0.20839962
A41: EBIT margin, reported | B41: =B13/B6 -> 0.21454935 | C41: =C13/C6 -> 0.15307049 | D41: =D13/D6 -> 0.22995857 | E41: =E13/E6 -> 0.20782616 | F41: =F13/F6 -> 0.12108793 | G41: =G13/G6 -> 0.13426662
A42: EBIT margin excl. 2023 one-off reserves | B42: =B13/B6 -> 0.21454935 | C42: =(C13+935)/C6 -> 0.24735303 | D42: =D13/D6 -> 0.22995857 | E42: =E13/E6 -> 0.20782616 | F42: =F13/F6 -> 0.12108793 | G42: =G13/G6 -> 0.13426662 | H42: Adds back the USD 935m of one-off reserves in 2023 G&A
A43: SBC in % of revenue | B43: =B24/B6 -> 0.11072747 | C43: =C24/C6 -> 0.11293738 | D43: =D24/D6 -> 0.12673392 | E43: =E24/E6 -> 0.13005473 | F43: =F24/F6 -> 0.14567809 | G43: =G24/G6 -> 0.14269806
A44: FCF margin | B44: =B22/B6 -> 0.40540541 | C44: =C22/C6 -> 0.38691136 | D44: =D22/D6 -> 0.40389119 | E44: =E22/E6 -> 0.3768483 | F44: =F22/F6 -> 0.51099106 | G44: =G22/G6 -> 0.47041044
...

Sheet WACC
A1: Cost of capital (WACC)
A3: Component | B3: Value | C3: Comment
A4: Risk-free rate | B4: =Inputs!$B$20 -> 0.0528
A5: Raw beta | B5: =Inputs!$B$22 -> 1.24
A6: Adjusted beta | B6: =0.67*B5+0.33 -> 1.1608 | C6: Blume adjustment: 0.67 x raw beta + 0.33 x 1
A7: Equity risk premium | B7: =Inputs!$B$21 -> 0.0423
A8: Cost of equity | B8: =B4+B6*B7 -> 0.10190184 | C8: CAPM
A9: Pre-tax cost of debt | B9: =Inputs!$B$23 -> 0.0476
A10: Tax rate | B10: =Inputs!$B$25 -> 0.21
A11: After-tax cost of debt | B11: =B9*(1-B10) -> 0.037604
A12: Market value of equity (USDm) | B12: =Inputs!$B$6*Inputs!$B$8 -> 97260.81 | C12: Share price x shares outstanding
A13: Debt (USDm) | B13: =Inputs!$B$24 -> 2476
A14: Weight of debt | B14: =B13/(B12+B13) -> 0.024825338 | C14: Very little debt, so WACC is almost the cost of equity
A15: WACC | B15: =(1-B14)*B8+B14*B11 -> 0.10030562
A18: WACC is high mainly because of the risk-free rate (10y Treasury above 5% in Oct 2026).

Sheet DCF
A1: DCF valuation (USD million)
A2: Valuation date 31.12.2025. Five-year forecast plus a normalised terminal year. EBIT is after stock-based compensation (GAAP).
B4: 2024A | C4: 2025A | D4: 2026E | E4: 2027E | F4: 2028E | G4: 2029E | H4: 2030E | I4: Terminal | K4: Reasoning
A5: Assumptions
A6: Revenue growth | B6: =Historicals!D34 -> 0.11949178 | C6: =Historicals!E34 -> 0.10259413 | D6: 0.155 | E6: 0.12 | F6: 0.11 | G6: 0.1 | H6: 0.09 | I6: 0.03 | K6: 2026: guidance "at least mid-teens" incl. ~3pt FX tailwind. 2027-28 close to consensus (+12% / +11%), then slowing as the core market matures. Terminal: nominal growth of travel.
A7: EBIT margin (after SBC) | B7: =Historicals!D41 -> 0.22995857 | C7: =Historicals!E41 -> 0.20782616 | D7: 0.215 | E7: 0.23 | F7: 0.25 | G7: 0.265 | H7: 0.27 | I7: 0.28 | K7: 2025: 20.8%. 2026 guidance: adj. EBITDA margin at least 35.5%. I let margins rise because SBC should grow slower than revenue. Terminal 28%, still below Booking (33%).
A8: D&A (% of revenue) | D8: 0.007 | E8: 0.007 | F8: 0.007 | G8: 0.007 | H8: 0.007 | I8: 0.007 | K8: 2025: USD 91m, 0.7% of revenue
A9: Capex (% of revenue) | D9: 0.004 | E9: 0.004 | F9: 0.004 | G9: 0.004 | H9: 0.004 | I9: 0.004 | K9: 2025: USD 33m, 0.3%. Asset-light, mostly software
A10: Working capital inflow (% of revenue increase) | D10: 0.12 | E10: 0.12 | F10: 0.12 | G10: 0.12 | H10: 0.12 | I10: 0.12 | K10: Guests pay at booking, before revenue is recognised. Unearned fees are ~14% of revenue and grow with it
A11: Memo: SBC (% of revenue) | B11: =Historicals!D43 -> 0.12673392 | C11: =Historicals!E43 -> 0.13005473 | D11: 0.125 | E11: 0.12 | F11: 0.115 | G11: 0.11 | H11: 0.105 | I11: 0.09 | K11: 2025: 13.0%. Mgmt expects SBC to grow slower than revenue. Only needed for the SBC switch below
A12: SBC treated as a cost (100% = base case) | C12: 1 | K12: Base case 100%: I treat SBC as a real cost, just paid in shares instead of cash. 0% = SBC added back, like the company's "adjusted" FCF
A14: Free cash flow
A15: Revenue | B15: =Historicals!D6 -> 11102 | C15: =Historicals!E6 -> 12241 | D15: =C15*(1+D6) -> 14138.355 | E15: =D15*(1+E6) -> 15834.958 | F15: =E15*(1+F6) -> 17576.803 | G15: =F15*(1+G6) -> 19334.483 | H15: =G15*(1+H6) -> 21074.587 | I15: =H15*(1+I6) -> 21706.824
A16: growth | B16: =Historicals!D34 -> 0.11949178 | C16: =C15/B15-1 -> 0.10259413 | D16: =D15/C15-1 -> 0.155 | E16: =E15/D15-1 -> 0.12 | F16: =F15/E15-1 -> 0.11 | G16: =G15/F15-1 -> 0.1 | H16: =H15/G15-1 -> 0.09 | I16: =I15/H15-1 -> 0.03
A17: EBIT (after SBC) | B17: =Historicals!D13 -> 2553 | C17: =Historicals!E13 -> 2544 | D17: =D15*D7 -> 3039.7463 | E17: =E15*E7 -> 3642.0402 | F17: =F15*F7 -> 4394.2007 | G17: =G15*G7 -> 5123.6381 | H17: =H15*H7 -> 5690.1384 | I17: =I15*I7 -> 6077.9108
A18: margin | B18: =B17/B15 -> 0.22995857 | C18: =C17/C15 -> 0.20782616 | D18: =D17/D15 -> 0.215 | E18: =E17/E15 -> 0.23 | F18: =F17/F15 -> 0.25 | G18: =G17/G15 -> 0.265 | H18: =H17/H15 -> 0.27 | I18: =I17/I15 -> 0.28
A19: Less: taxes on EBIT | D19: =-D17*Inputs!$B$25 -> -638.34673 | E19: =-E17*Inputs!$B$25 -> -764.82845 | F19: =-F17*Inputs!$B$25 -> -922.78215 | G19: =-G17*Inputs!$B$25 -> -1075.964 | H19: =-H17*Inputs!$B$25 -> -1194.9291 | I19: =-I17*Inputs!$B$25 -> -1276.3613
A20: NOPAT | D20: =D17+D19 -> 2401.3996 | E20: =E17+E19 -> 2877.2118 | F20: =F17+F19 -> 3471.4186 | G20: =G17+G19 -> 4047.6741 | H20: =H17+H19 -> 4495.2093 | I20: =I17+I19 -> 4801.5495
A21: Plus: D&A | D21: =D15*D8 -> 98.968485 | E21: =E15*E8 -> 110.8447 | F21: =F15*F8 -> 123.03762 | G21: =G15*G8 -> 135.34138 | H21: =H15*H8 -> 147.52211 | I21: =I15*I8 -> 151.94777
A22: Less: capex | B22: =-Historicals!D23 -> -34 | C22: =-Historicals!E23 -> -33 | D22: =-D15*D9 -> -56.55342 | E22: =-E15*E9 -> -63.33983 | F22: =-F15*F9 -> -70.307212 | G22: =-G15*G9 -> -77.337933 | H22: =-H15*H9 -> -84.298347 | I22: =-I15*I9 -> -86.827297
A23: Plus: working capital inflow | D23: =(D15-C15)*D10 -> 227.6826 | E23: =(E15-D15)*E10 -> 203.59231 | F23: =(F15-E15)*F10 -> 209.02144 | G23: =(G15-F15)*G10 -> 210.92164 | H23: =(H15-G15)*H10 -> 208.81242 | I23: =(I15-H15)*I10 -> 75.868512
A24: Plus: SBC add-back (only if switch < 100%) | D24: =D15*D11*(1-$C$12) -> 0 | E24: =E15*E11*(1-$C$12) -> 0 | F24: =F15*F11*(1-$C$12) -> 0 | G24: =G15*G11*(1-$C$12) -> 0 | H24: =H15*H11*(1-$C$12) -> 0 | I24: =I15*I11*(1-$C$12) -> 0 | K24: Zero in the base case
A25: Unlevered free cash flow | B25: =Historicals!D22 -> 4484 | C25: =Historicals!E22 -> 4613 | D25: =SUM(D20:D24) -> 2671.4973 | E25: =SUM(E20:E24) -> 3128.309 | F25: =SUM(F20:F24) -> 3733.1704 | G25: =SUM(G20:G24) -> 4316.5991 | H25: =SUM(H20:H24) -> 4767.2455 | I25: =SUM(I20:I24) -> 4942.5385 | K25: 2024A/2025A = reported FCF (incl. SBC add-back and interest income), so not like-for-like
A26: in % of revenue | B26: =B25/B15 -> 0.40389119 | C26: =C25/C15 -> 0.3768483 | D26: =D25/D15 -> 0.1889539 | E26: =E25/E15 -> 0.19755714 | F26: =F25/F15 -> 0.21239189 | G26: =G25/G15 -> 0.22325909 | H26: =H25/H15 -> 0.22620826 | I26: =I25/I15 -> 0.22769515 | K26: FCF after SBC on Historicals: 25% in 2025
A28: Discounting (mid-year convention)
A29: WACC | C29: =IF($C$64>0,$C$64,WACC!$B$15) -> 0.10030562 | K29: From the WACC sheet; the override in C64 is only used by the sensitivity table
A30: Discount period (years) | D30: 0.5 | E30: 1.5 | F30: 2.5 | G30: 3.5 | H30: 4.5
A31: Discount factor | D31: =1/(1+$C$29)^D30 -> 0.95333016 | E31: =1/(1+$C$29)^E30 -> 0.86642306 | F31: =1/(1+$C$29)^F30 -> 0.78743854 | G31: =1/(1+$C$29)^G30 -> 0.71565438 | H31: =1/(1+$C$29)^H30 -> 0.65041418
A32: Present value of free cash flow | D32: =D25*D31 -> 2546.8189 | E32: =E25*E31 -> 2710.439 | F32: =F25*F31 -> 2939.6423 | G32: =G25*G31 -> 3089.1931 | H32: =H25*H31 -> 3100.6841
A34: Valuation
A35: Sum of PV of free cash flows 2026-2030 | C35: =SUM(D32:H32) -> 14386.777
A36: Terminal value at end of 2030 | C36: =I25/($C$29-I6) -> 70300.756 | D36: Terminal free cash flow / (WACC - g)
A37: PV of terminal value | C37: =C36/(1+$C$29)^5 -> 43590.648 | D37: Discounted over 5 full years
A38: Enterprise value | C38: =C35+C37 -> 57977.426
A39: Plus: net cash | C39: =Inputs!$B$16 -> 9015 | D39: 31.12.2025; customer funds excluded
A40: Equity value | C40: =C38+C39 -> 66992.426
A41: Value per share at 31.12.2025 (USD) | C41: =C40/Inputs!$B$9 -> 107.53198 | D41: Diluted shares
A42: Value per share at analysis date (USD) | C42: =C41*(1+WACC!$B$8)^Inputs!$B$29 -> 115.68823 | D42: Rolled forward at the cost of equity to 02.10.2026 (no dividend)
A43: Share price at analysis date (USD) | C43: =Inputs!$B$6 -> 162.43
A44: Upside / (downside) | C44: =C42/C43-1 -> -0.28776564
...

Sheet Comps
A1: Trading comparables: online travel and hotel franchisors
A2: Estimates and prices from MarketScreener, prices within a week of the analysis date (02.10.2026). Millions in reporting currency.
A3: USD-CNY rate (Trip.com reports in CNY) | B3: 6.7038 | C3: FRED (DEXCHUS), 02.10.2026
A5: Company | B5: Group | C5: Ccy | D5: Price (USD) | E5: Price date | F5: Shares (m) | G5: Market cap | H5: Net debt FY25 | I5: EV | J5: Sales 25A | K5: Sales 26E | L5: Sales 27E | M5: EBITDA 26E | N5: EBIT 26E | O5: EBIT 27E | P5: EPS 26E | Q5: EPS 27E | R5: Sales growth 27E | S5: EBIT margin 26E | T5: EV/EBITDA 26E | U5: EV/EBIT 26E | V5: EV/EBIT 27E | W5: P/E 26E | X5: P/E 27E
A6: Booking Holdings | B6: Online travel | C6: USD | D6: 160.34 | E6: 46304 | F6: 751.38 | G6: =D6*F6*IF(C6="CNY",$B$3,1) -> 120476.27 | H6: 1533 | I6: =G6+H6 -> 122009.27 | J6: 26917 | K6: 29251 | L6: 31970 | M6: 10847 | N6: 10337 | O6: 11559 | P6: 10.5 | Q6: 12.11 | R6: =L6/K6-1 -> 0.092954087 | S6: =N6/K6 -> 0.35338963 | T6: =I6/M6 -> 11.248204 | U6: =I6/N6 -> 11.80316 | V6: =I6/O6 -> 10.555348 | W6: =D6*IF(C6="CNY",$B$3,1)/P6 -> 15.270476 | X6: =D6*IF(C6="CNY",$B$3,1)/Q6 -> 13.240297
A7: Expedia Group | B7: Online travel | C7: USD | D7: 264.17 | E7: 46290 | F7: 120.019 | G7: =D7*F7*IF(C7="CNY",$B$3,1) -> 31705.419 | H7: 428 | I7: =G7+H7 -> 32133.419 | J7: 14733 | K7: 16201 | L7: 17348 | M7: 4126 | N7: 2843 | O7: 3175 | P7: 18.53 | Q7: 21.23 | R7: =L7/K7-1 -> 0.070798099 | S7: =N7/K7 -> 0.17548299 | T7: =I7/M7 -> 7.7880318 | U7: =I7/N7 -> 11.302645 | V7: =I7/O7 -> 10.120762 | W7: =D7*IF(C7="CNY",$B$3,1)/P7 -> 14.256341 | X7: =D7*IF(C7="CNY",$B$3,1)/Q7 -> 12.443241
A8: Trip.com Group | B8: Online travel | C8: CNY | D8: 38.9 | E8: 46304 | F8: 629.705 | G8: =D8*F8*IF(C8="CNY",$B$3,1) -> 164213.1 | H8: -15686 | I8: =G8+H8 -> 148527.1 | J8: 62409 | K8: 66591 | L8: 72620 | M8: 16032 | N8: 11773 | O8: 17292 | P8: 10.8 | Q8: 22.93 | R8: =L8/K8-1 -> 0.09053776 | S8: =N8/K8 -> 0.17679566 | T8: =I8/M8 -> 9.2644147 | U8: =I8/N8 -> 12.615909 | V8: =I8/O8 -> 8.5893533 | W8: =D8*IF(C8="CNY",$B$3,1)/P8 -> 24.146094 | X8: =D8*IF(C8="CNY",$B$3,1)/Q8 -> 11.372779
A9: Marriott International | B9: Hotel franchisor | C9: USD | D9: 352.03 | E9: 46290 | F9: 260.766 | G9: =D9*F9*IF(C9="CNY",$B$3,1) -> 91797.455 | H9: 15846 | I9: =G9+H9 -> 107643.45 | J9: 26186 | K9: 27783 | L9: 29479 | M9: 6005 | N9: 4907 | O9: 5436 | P9: 11.16 | Q9: 13.06 | R9: =L9/K9-1 -> 0.061044524 | S9: =N9/K9 -> 0.1766188 | T9: =I9/M9 -> 17.925638 | U9: =I9/N9 -> 21.936714 | V9: =I9/O9 -> 19.80196 | W9: =D9*IF(C9="CNY",$B$3,1)/P9 -> 31.543907 | X9: =D9*IF(C9="CNY",$B$3,1)/Q9 -> 26.954824
A10: Hilton Worldwide | B10: Hotel franchisor | C10: USD | D10: 320.28 | E10: 46293 | F10: 225.065 | G10: =D10*F10*IF(C10="CNY",$B$3,1) -> 72083.818 | H10: 11489 | I10: =G10+H10 -> 83572.818 | J10: 12039 | K10: 13034 | L10: 14164 | M10: 4064 | N10: 3342 | O10: 3845 | P10: 8.376 | Q10: 9.975 | R10: =L10/K10-1 -> 0.086696333 | S10: =N10/K10 -> 0.25640632 | T10: =I10/M10 -> 20.564178 | U10: =I10/N10 -> 25.006828 | V10: =I10/O10 -> 21.735453 | W10: =D10*IF(C10="CNY",$B$3,1)/P10 -> 38.237822 | X10: =D10*IF(C10="CNY",$B$3,1)/Q10 -> 32.108271
A11: Airbnb (consensus) | B11: Marketplace | C11: USD | D11: =Inputs!$B$6 -> 162.43 | E11: =Inputs!$B$7 -> 46297 | F11: =Inputs!$B$8 -> 598.786 | G11: =D11*F11*IF(C11="CNY",$B$3,1) -> 97260.81 | H11: =-Inputs!$B$16 -> -9015 | I11: =G11+H11 -> 88245.81 | J11: 12241 | K11: 14170 | L11: 15825 | M11: 5044 | N11: 3174 | O11: 3782 | P11: 5.298 | Q11: 6.25 | R11: =L11/K11-1 -> 0.11679605 | S11: =N11/K11 -> 0.22399435 | T11: =I11/M11 -> 17.495204 | U11: =I11/N11 -> 27.802713 | V11: =I11/O11 -> 23.333107 | W11: =D11*IF(C11="CNY",$B$3,1)/P11 -> 30.658739 | X11: =D11*IF(C11="CNY",$B$3,1)/Q11 -> 25.9888
A13: Airbnb's EBITDA is "adjusted", i.e. before USD 1.6bn of SBC, while the peers have much less SBC. So I rely on EV/EBIT and P/E, which include SBC for everyone.
A14: Trip.com: 2025 earnings include a one-off gain, so 2026E looks distorted. I keep it in but don't put much weight on its P/E.
A15: Net debt at FY2025 year-end for all companies. Airbnb's net cash shows as negative net debt.
A16: Peer share counts: MarketScreener 2026 figures (closest to today after buybacks). Airbnb: 10-Q cover page.
A18: Peer multiples summary
A19: Statistic | B19: EV/EBITDA 26E | C19: EV/EBIT 26E | D19: EV/EBIT 27E | E19: P/E 26E | F19: P/E 27E | G19: Sales growth 27E | H19: EBIT margin 26E
A20: Online travel: median | B20: =MEDIAN(T6:T8) -> 9.2644147 | C20: =MEDIAN(U6:U8) -> 11.80316 | D20: =MEDIAN(V6:V8) -> 10.120762 | E20: =MEDIAN(W6:W8) -> 15.270476 | F20: =MEDIAN(X6:X8) -> 12.443241 | G20: =MEDIAN(R6:R8) -> 0.09053776 | H20: =MEDIAN(S6:S8) -> 0.17679566
A21: Online travel: low | B21: =MIN(T6:T8) -> 7.7880318 | C21: =MIN(U6:U8) -> 11.302645 | D21: =MIN(V6:V8) -> 8.5893533 | E21: =MIN(W6:W8) -> 14.256341 | F21: =MIN(X6:X8) -> 11.372779 | G21: =MIN(R6:R8) -> 0.070798099 | H21: =MIN(S6:S8) -> 0.17548299
A22: Online travel: high | B22: =MAX(T6:T8) -> 11.248204 | C22: =MAX(U6:U8) -> 12.615909 | D22: =MAX(V6:V8) -> 10.555348 | E22: =MAX(W6:W8) -> 24.146094 | F22: =MAX(X6:X8) -> 13.240297 | G22: =MAX(R6:R8) -> 0.092954087 | H22: =MAX(S6:S8) -> 0.35338963
A23: Hotel franchisors: median | B23: =MEDIAN(T9:T10) -> 19.244908 | C23: =MEDIAN(U9:U10) -> 23.471771 | D23: =MEDIAN(V9:V10) -> 20.768707 | E23: =MEDIAN(W9:W10) -> 34.890865 | F23: =MEDIAN(X9:X10) -> 29.531547 | G23: =MEDIAN(R9:R10) -> 0.073870428 | H23: =MEDIAN(S9:S10) -> 0.21651256
A24: Hotel franchisors: low | B24: =MIN(T9:T10) -> 17.925638 | C24: =MIN(U9:U10) -> 21.936714 | D24: =MIN(V9:V10) -> 19.80196 | E24: =MIN(W9:W10) -> 31.543907 | F24: =MIN(X9:X10) -> 26.954824 | G24: =MIN(R9:R10) -> 0.061044524 | H24: =MIN(S9:S10) -> 0.1766188
A25: Hotel franchisors: high | B25: =MAX(T9:T10) -> 20.564178 | C25: =MAX(U9:U10) -> 25.006828 | D25: =MAX(V9:V10) -> 21.735453 | E25: =MAX(W9:W10) -> 38.237822 | F25: =MAX(X9:X10) -> 32.108271 | G25: =MAX(R9:R10) -> 0.086696333 | H25: =MAX(S9:S10) -> 0.25640632
A26: Airbnb | B26: =T11 -> 17.495204 | C26: =U11 -> 27.802713 | D26: =V11 -> 23.333107 | E26: =W11 -> 30.658739 | F26: =X11 -> 25.9888 | G26: =R11 -> 0.11679605 | H26: =S11 -> 0.22399435
A27: Airbnb trades at more than 2x the EV/EBIT of the online travel agencies and above the hotel franchisors, with faster growth (11.7% vs. ~9% and ~7% in 2027E).
A29: Implied value per Airbnb share (USD)
A30: Multiple | B30: Airbnb metric | C30: Low | D30: Median | E30: High | F30: Basis
A31: EV/EBIT 26E, online travel | B31: =N11 -> 3174 | C31: =($B31*C21+Inputs!$B$16)/Inputs!$B$9 -> 72.053924 | D31: =($B31*C20+Inputs!$B$16)/Inputs!$B$9 -> 74.603902 | E31: =($B31*C22+Inputs!$B$16)/Inputs!$B$9 -> 78.744615 | F31: EBIT x multiple + net cash, per diluted share
A32: EV/EBIT 26E, hotel franchisors | B32: =N11 -> 3174 | C32: =($B32*C24+Inputs!$B$16)/Inputs!$B$9 -> 126.23135 | D32: =($B32*C23+Inputs!$B$16)/Inputs!$B$9 -> 134.05201 | E32: =($B32*C25+Inputs!$B$16)/Inputs!$B$9 -> 141.87267 | F32: EBIT x multiple + net cash, per diluted share
A33: P/E 26E, online travel | B33: =P11 -> 5.298 | C33: =$B33*E21 -> 75.530095 | D33: =$B33*E20 -> 80.902983 | E33: =$B33*E22 -> 127.92601 | F33: EPS x peer P/E
A34: P/E 26E, hotel franchisors | B34: =P11 -> 5.298 | C34: =$B34*E24 -> 167.11962 | D34: =$B34*E23 -> 184.8518 | E34: =$B34*E25 -> 202.58398 | F34: EPS x peer P/E

Sheet Football Field
A1: Valuation summary (football field)
A2: USD per share at the analysis date (02.10.2026). Chart: each line goes from a method's low to its high value, red dashed line = share price. Columns F-G are helper columns for the chart.
A4: Method | B4: Low | C4: High | D4: Range | E4: Basis | F4: Share price | G4: DCF base case
A5: DCF: WACC / terminal growth | B5: =MIN(DCF!E69:G71) -> 104.07358 | C5: =MAX(DCF!E69:G71) -> 131.14775 | D5: =C5-B5 -> 27.074172 | E5: WACC +/-0.5pp, growth 2.5-3.5% | F5: =$B$14 -> 162.43 | G5: =$B$15 -> 115.68823
A6: DCF: SBC treatment | B6: =MIN(DCF!D76:H80) -> 105.24126 | C6: =MAX(DCF!D76:H80) -> 169.50426 | D6: =C6-B6 -> 64.262993 | E6: SBC 0-100% treated as cost, terminal margin 24-32% | F6: =$B$14 -> 162.43
A7: EV/EBIT 26E, online travel | B7: =Comps!C31 -> 72.053924 | C7: =Comps!E31 -> 78.744615 | D7: =C7-B7 -> 6.6906912 | E7: Peer low-high | F7: =$B$14 -> 162.43
A8: EV/EBIT 26E, hotel franchisors | B8: =Comps!C32 -> 126.23135 | C8: =Comps!E32 -> 141.87267 | D8: =C8-B8 -> 15.641318 | E8: Peer low-high | F8: =$B$14 -> 162.43
A9: P/E 26E, online travel | B9: =Comps!C33 -> 75.530095 | C9: =Comps!E33 -> 127.92601 | D9: =C9-B9 -> 52.395913 | E9: Peer low-high | F9: =$B$14 -> 162.43
A10: P/E 26E, hotel franchisors | B10: =Comps!C34 -> 167.11962 | C10: =Comps!E34 -> 202.58398 | D10: =C10-B10 -> 35.464365 | E10: Peer low-high | F10: =$B$14 -> 162.43
A11: Analyst price targets | B11: =Inputs!$B$30 -> 135 | C11: =Inputs!$B$31 -> 220 | D11: =C11-B11 -> 85 | E11: MarketScreener consensus, 43 analysts | F11: =$B$14 -> 162.43
A12: 52-week trading range | B12: =Inputs!$B$32 -> 110.81 | C12: =Inputs!$B$33 -> 193.45 | D12: =C12-B12 -> 82.64 | E12: Nasdaq, 52-week low and high | F12: =$B$14 -> 162.43
A14: Share price at analysis date | B14: =Inputs!$B$6 -> 162.43
A15: DCF value (base case) | B15: =DCF!$C$42 -> 115.68823

Sheet Charts
A1: Charts: why the rating is SELL
A2: All figures are linked to the model.
A4: 1. Reported free cash flow = SBC + free cash flow after SBC (USD m)
B5: FY2022 | C5: FY2023 | D5: FY2024 | E5: FY2025
A6: Free cash flow after SBC | B6: =Historicals!B22-Historicals!B24 -> 2475 | C6: =Historicals!C22-Historicals!C24 -> 2717 | D6: =Historicals!D22-Historicals!D24 -> 3077 | E6: =Historicals!E22-Historicals!E24 -> 3021
A7: Stock-based compensation | B7: =Historicals!B24 -> 930 | C7: =Historicals!C24 -> 1120 | D7: =Historicals!D24 -> 1407 | E7: =Historicals!E24 -> 1592
A8: SBC in % of reported FCF | B8: =Historicals!B24/Historicals!B22 -> 0.27312775 | C8: =Historicals!C24/Historicals!C22 -> 0.29189471 | D8: =Historicals!D24/Historicals!D22 -> 0.31378234 | E8: =Historicals!E24/Historicals!E22 -> 0.34511164
A11: 2. EV / EBIT 2026E (EBIT after stock-based pay for everyone)
A12: Company | B12: EV/EBIT 26E | C12: Sales growth 27E
A13: =Comps!A6 -> Booking Holdings | B13: =Comps!U6 -> 11.80316 | C13: =Comps!R6 -> 0.092954087
A14: =Comps!A7 -> Expedia Group | B14: =Comps!U7 -> 11.302645 | C14: =Comps!R7 -> 0.070798099
A15: =Comps!A8 -> Trip.com Group | B15: =Comps!U8 -> 12.615909 | C15: =Comps!R8 -> 0.09053776
A16: =Comps!A9 -> Marriott International | B16: =Comps!U9 -> 21.936714 | C16: =Comps!R9 -> 0.061044524
A17: =Comps!A10 -> Hilton Worldwide | B17: =Comps!U10 -> 25.006828 | C17: =Comps!R10 -> 0.086696333
A18: =Comps!A11 -> Airbnb (consensus) | B18: =Comps!U11 -> 27.802713 | C18: =Comps!R11 -> 0.11679605
A20: 3. DCF value by share of SBC counted as a cost (terminal margin 28%)
A21: SBC counted as cost | B21: DCF value (USD) | C21: Share price (USD)
A22: =TEXT(DCF!C76,"0%") -> 100% | B22: =DCF!F76 -> 115.68823 | C22: =Inputs!$B$6 -> 162.43
A23: =TEXT(DCF!C77,"0%") -> 75% | B23: =DCF!F77 -> 126.53049 | C23: =Inputs!$B$6 -> 162.43
A24: =TEXT(DCF!C78,"0%") -> 50% | B24: =DCF!F78 -> 137.37276 | C24: =Inputs!$B$6 -> 162.43
A25: =TEXT(DCF!C79,"0%") -> 25% | B25: =DCF!F79 -> 148.21503 | C25: =Inputs!$B$6 -> 162.43
A26: =TEXT(DCF!C80,"0%") -> 0% | B26: =DCF!F80 -> 159.05729 | C26: =Inputs!$B$6 -> 162.43
A28: 4. Revenue growth: reported, my forecast, and what the share price needs
A29: Extra growth needed p.a. 2026-30 | B29: 0.0952
A30: Period | B30: Reported | C30: My forecast | D30: Needed for the price
A31: 2023 | B31: =Historicals!C34 -> 0.1807358
A32: 2024 | B32: =Historicals!D34 -> 0.11949178
A33: 2025 | B33: =Historicals!E34 -> 0.10259413
A34: H1 2026 | B34: =Historicals!G34 -> 0.17101341
A35: 2026E | C35: =DCF!D6 -> 0.155 | D35: =C35+$B$29 -> 0.2502
A36: 2027E | C36: =DCF!E6 -> 0.12 | D36: =C36+$B$29 -> 0.2152
A37: 2028E | C37: =DCF!F6 -> 0.11 | D37: =C37+$B$29 -> 0.2052
A38: 2029E | C38: =DCF!G6 -> 0.1 | D38: =C38+$B$29 -> 0.1952
A39: 2030E | C39: =DCF!H6 -> 0.09 | D39: =C39+$B$29 -> 0.1852
A41: H1 2026 growth includes about 3 points of currency tailwind.
A42: Reverse DCF: this much extra growth in every year (DCF!D6:H6) gets the value to the share price.

Sheet Sources
B1: Sources
B3: Document | C3: Link
B4: Airbnb Q2 2026 shareholder letter (Form 8-K, Ex. 99.1) | C4: https://www.sec.gov/Archives/edgar/data/0001559720/000119312526337928/d70413dex991.htm
B5: Airbnb Q4 2025 shareholder letter | C5: https://s26.q4cdn.com/656283129/files/doc_financials/2025/q4/Airbnb_Q4-2025-Shareholder-Letter-Final.pdf
B6: Airbnb Q4 2023 shareholder letter (Form 8-K, Ex. 99.1) | C6: https://www.sec.gov/Archives/edgar/data/1559720/000119312524033706/d646462dex991.htm
B7: Airbnb Form 10-K 2025 | C7: https://www.sec.gov/Archives/edgar/data/1559720/000155972026000004/abnb-20251231.htm
B8: Airbnb Form 10-Q Q2 2026 | C8: https://www.sec.gov/Archives/edgar/data/0001559720/000155972026000027/abnb-20260630.htm
B9: Airbnb Form 8-K: USD 2.5bn senior notes, March 2026 | C9: https://www.sec.gov/Archives/edgar/data/1559720/000119312526108514/d106317d8k.htm
B10: Airbnb consensus estimates and share price (MarketScreener) | C10: https://www.marketscreener.com/quote/stock/AIRBNB-INC-116310849/finances/
B11: Airbnb analyst price targets (MarketScreener) | C11: https://www.marketscreener.com/quote/stock/AIRBNB-INC-121407285/consensus/
B12: Booking Holdings (MarketScreener) | C12: https://www.marketscreener.com/quote/stock/BOOKING-HOLDINGS-INC-41613106/finances/
B13: Expedia Group (MarketScreener) | C13: https://www.marketscreener.com/quote/stock/EXPEDIA-GROUP-INC-9605918/finances/
B14: Trip.com Group (MarketScreener) | C14: https://www.marketscreener.com/quote/stock/TRIP-COM-GROUP-LIMITED-40311225/finances/
... B23: Airbnb beta (Yahoo Finance) | C23: https://finance.yahoo.com/quote/ABNB
